Workbook

Sheet Sheet1
B2: Instance | C2: Uncapacitated Objective | D2: Time (s) | E2: Iterations | F2: Capacitated Objective | G2: Extra Time (s) | H2: Feasible Routes | I2: Infeasible Routes | J2: Total | L2: Instance | M2: Avg Time | O2: Instance | P2: Avg Number of Valid Routes | Q2: Avg Number of Infeasible Routes | S2: Nodes | T2: Median Routes Checked
B3: l_4_25_1 | C3: 4585.85 | D3: 0.29 | E3: 0 | F3: 4585.85 | G3: 0 | H3: 41 | I3: 28 | J3: =H3+I3 -> 69 | L3: {=LEFT(INDEX($B:$B, ROW($B$3) + (ROW()-ROW($G$3))*5), LEN(INDEX($B:$B, ROW($B$3) + (ROW()-ROW($G$3))*5))-2)} -> l_4_25 | M3: =ROUND(AVERAGE(OFFSET($D$3,(ROW()-ROW($O$3))*5,0,5,1)),1) -> 0.9 | O3: {=LEFT(INDEX($B:$B, ROW($B$3) + (ROW()-ROW($G$3))*5), LEN(INDEX($B:$B, ROW($B$3) + (ROW()-ROW($G$3))*5))-2)} -> l_4_25 | P3: =AVERAGE(OFFSET($H$3,(ROW()-ROW($O$3))*5,0,5,1)) -> 75.6 | Q3: =ROUND(AVERAGE(OFFSET($I$3,(ROW()-ROW($O$3))*5,0,5,1)),2) -> 30.6 | S3: 25 | T3: {=MEDIAN(_xlfn._xlws.FILTER($J$1:$J$122,ISNUMBER(SEARCH(INDIRECT("RC[-1]",0),$B$1:$B$122))))} -> 52
B4: l_4_25_2 | C4: 4017.93 | D4: 1.41 | E4: 0 | F4: 4017.93 | G4: 0 | H4: 119 | I4: 31 | J4: =H4+I4 -> 150 | L4: {=LEFT(INDEX($B:$B, ROW($B$3) + (ROW()-ROW($G$3))*5), LEN(INDEX($B:$B, ROW($B$3) + (ROW()-ROW($G$3))*5))-2)} -> l_4_35 | M4: =ROUND(AVERAGE(OFFSET($D$3,(ROW()-ROW($O$3))*5,0,5,1)),1) -> 2.6 | O4: {=LEFT(INDEX($B:$B, ROW($B$3) + (ROW()-ROW($G$3))*5), LEN(INDEX($B:$B, ROW($B$3) + (ROW()-ROW($G$3))*5))-2)} -> l_4_35 | P4: =AVERAGE(OFFSET($H$3,(ROW()-ROW($O$3))*5,0,5,1)) -> 204.8 | Q4: =ROUND(AVERAGE(OFFSET($I$3,(ROW()-ROW($O$3))*5,0,5,1)),2) -> 108.4 | S4: 35 | T4: {=MEDIAN(_xlfn._xlws.FILTER($J$1:$J$122,ISNUMBER(SEARCH(INDIRECT("RC[-1]",0),$B$1:$B$122))))} -> 92.5
B5: l_4_25_3 | C5: 4713.75 | D5: 0.66 | E5: 0 | F5: 4713.75 | G5: 0 | H5: 43 | I5: 22 | J5: =H5+I5 -> 65 | L5: {=LEFT(INDEX($B:$B, ROW($B$3) + (ROW()-ROW($G$3))*5), LEN(INDEX($B:$B, ROW($B$3) + (ROW()-ROW($G$3))*5))-2)} -> l_4_50 | M5: =ROUND(AVERAGE(OFFSET($D$3,(ROW()-ROW($O$3))*5,0,5,1)),1) -> 7.8 | O5: {=LEFT(INDEX($B:$B, ROW($B$3) + (ROW()-ROW($G$3))*5), LEN(INDEX($B:$B, ROW($B$3) + (ROW()-ROW($G$3))*5))-2)} -> l_4_50 | P5: =AVERAGE(OFFSET($H$3,(ROW()-ROW($O$3))*5,0,5,1)) -> 565.2 | Q5: =ROUND(AVERAGE(OFFSET($I$3,(ROW()-ROW($O$3))*5,0,5,1)),2) -> 341 | S5: 50 | T5: {=MEDIAN(_xlfn._xlws.FILTER($J$1:$J$122,ISNUMBER(SEARCH(INDIRECT("RC[-1]",0),$B$1:$B$122))))} -> 305.5
B6: l_4_25_4 | C6: 3872.6 | D6: 0.58 | E6: 0 | F6: 3872.6 | G6: 0 | H6: 77 | I6: 36 | J6: =H6+I6 -> 113 | L6: {=LEFT(INDEX($B:$B, ROW($B$3) + (ROW()-ROW($G$3))*5), LEN(INDEX($B:$B, ROW($B$3) + (ROW()-ROW($G$3))*5))-2)} -> l_4_100 | M6: =ROUND(AVERAGE(OFFSET($D$3,(ROW()-ROW($O$3))*5,0,5,1)),1) -> 264.1 | O6: {=LEFT(INDEX($B:$B, ROW($B$3) + (ROW()-ROW($G$3))*5), LEN(INDEX($B:$B, ROW($B$3) + (ROW()-ROW($G$3))*5))-2)} -> l_4_100 | P6: =AVERAGE(OFFSET($H$3,(ROW()-ROW($O$3))*5,0,5,1)) -> 12148.8 | Q6: =ROUND(AVERAGE(OFFSET($I$3,(ROW()-ROW($O$3))*5,0,5,1)),2) -> 6317 | S6: 100 | T6: {=MEDIAN(_xlfn._xlws.FILTER($J$1:$J$122,ISNUMBER(SEARCH(INDIRECT("RC[-1]",0),$B$1:$B$122))))} -> 3413.5
B7: l_4_25_5 | C7: 3397.66 | D7: 1.65 | E7: 0 | F7: 3397.66 | G7: 0 | H7: 98 | I7: 36 | J7: =H7+I7 -> 134 | L7: {=LEFT(INDEX($B:$B, ROW($B$3) + (ROW()-ROW($G$3))*5), LEN(INDEX($B:$B, ROW($B$3) + (ROW()-ROW($G$3))*5))-2)} -> l_8_25 | M7: =ROUND(AVERAGE(OFFSET($D$3,(ROW()-ROW($O$3))*5,0,5,1)),1) -> 0.4 | O7: {=LEFT(INDEX($B:$B, ROW($B$3) + (ROW()-ROW($G$3))*5), LEN(INDEX($B:$B, ROW($B$3) + (ROW()-ROW($G$3))*5))-2)} -> l_8_25 | P7: =AVERAGE(OFFSET($H$3,(ROW()-ROW($O$3))*5,0,5,1)) -> 19 | Q7: =ROUND(AVERAGE(OFFSET($I$3,(ROW()-ROW($O$3))*5,0,5,1)),2) -> 8.8
B8: l_4_35_1 | C8: 5791.61 | D8: 2.02 | E8: 0 | F8: 5791.61 | G8: 0 | H8: 156 | I8: 98 | J8: =H8+I8 -> 254 | L8: {=LEFT(INDEX($B:$B, ROW($B$3) + (ROW()-ROW($G$3))*5), LEN(INDEX($B:$B, ROW($B$3) + (ROW()-ROW($G$3))*5))-2)} -> l_8_35 | M8: =ROUND(AVERAGE(OFFSET($D$3,(ROW()-ROW($O$3))*5,0,5,1)),1) -> 0.6 | O8: {=LEFT(INDEX($B:$B, ROW($B$3) + (ROW()-ROW($G$3))*5), LEN(INDEX($B:$B, ROW($B$3) + (ROW()-ROW($G$3))*5))-2)} -> l_8_35 | P8: =AVERAGE(OFFSET($H$3,(ROW()-ROW($O$3))*5,0,5,1)) -> 20.8 | Q8: =ROUND(AVERAGE(OFFSET($I$3,(ROW()-ROW($O$3))*5,0,5,1)),2) -> 15.8 | S8: Req Len | T8: Median Routes Checked
B9: l_4_35_2 | C9: 5470.93 | D9: 1.14 | E9: 0 | F9: 5470.93 | G9: 0 | H9: 83 | I9: 57 | J9: =H9+I9 -> 140 | L9: {=LEFT(INDEX($B:$B, ROW($B$3) + (ROW()-ROW($G$3))*5), LEN(INDEX($B:$B, ROW($B$3) + (ROW()-ROW($G$3))*5))-2)} -> l_8_50 | M9: =ROUND(AVERAGE(OFFSET($D$3,(ROW()-ROW($O$3))*5,0,5,1)),1) -> 1.8 | O9: {=LEFT(INDEX($B:$B, ROW($B$3) + (ROW()-ROW($G$3))*5), LEN(INDEX($B:$B, ROW($B$3) + (ROW()-ROW($G$3))*5))-2)} -> l_8_50 | P9: =AVERAGE(OFFSET($H$3,(ROW()-ROW($O$3))*5,0,5,1)) -> 59.6 | Q9: =ROUND(AVERAGE(OFFSET($I$3,(ROW()-ROW($O$3))*5,0,5,1)),2) -> 49.2 | S9: 4 | T9: {=MEDIAN(_xlfn._xlws.FILTER($J$1:$J$122,ISNUMBER(SEARCH(INDIRECT("RC[-1]",0),$B$1:$B$122))))} -> 378.5
B10: l_4_35_3 | C10: 5387.35 | D10: 3.19 | E10: 0 | F10: 5387.35 | G10: 0 | H10: 227 | I10: 163 | J10: =H10+I10 -> 390 | L10: {=LEFT(INDEX($B:$B, ROW($B$3) + (ROW()-ROW($G$3))*5), LEN(INDEX($B:$B, ROW($B$3) + (ROW()-ROW($G$3))*5))-2)} -> l_8_100 | M10: =ROUND(AVERAGE(OFFSET($D$3,(ROW()-ROW($O$3))*5,0,5,1)),1) -> 10.8 | O10: {=LEFT(INDEX($B:$B, ROW($B$3) + (ROW()-ROW($G$3))*5), LEN(INDEX($B:$B, ROW($B$3) + (ROW()-ROW($G$3))*5))-2)} -> l_8_100 | P10: =AVERAGE(OFFSET($H$3,(ROW()-ROW($O$3))*5,0,5,1)) -> 293 | Q10: =ROUND(AVERAGE(OFFSET($I$3,(ROW()-ROW($O$3))*5,0,5,1)),2) -> 328.8 | S10: 8 | T10: {=MEDIAN(_xlfn._xlws.FILTER($J$1:$J$122,ISNUMBER(SEARCH(INDIRECT("RC[-1]",0),$B$1:$B$122))))} -> 65.5
B11: l_4_35_4 | C11: 6257.5 | D11: 2.47 | E11: 0 | F11: 6257.5 | G11: 0 | H11: 204 | I11: 111 | J11: =H11+I11 -> 315 | L11: {=LEFT(INDEX($B:$B, ROW($B$3) + (ROW()-ROW($G$3))*5), LEN(INDEX($B:$B, ROW($B$3) + (ROW()-ROW($G$3))*5))-2)} -> n_4_25 | M11: =ROUND(AVERAGE(OFFSET($D$3,(ROW()-ROW($O$3))*5,0,5,1)),1) -> 0.2 | O11: {=LEFT(INDEX($B:$B, ROW($B$3) + (ROW()-ROW($G$3))*5), LEN(INDEX($B:$B, ROW($B$3) + (ROW()-ROW($G$3))*5))-2)} -> n_4_25 | P11: =AVERAGE(OFFSET($H$3,(ROW()-ROW($O$3))*5,0,5,1)) -> 36.2 | Q11: =ROUND(AVERAGE(OFFSET($I$3,(ROW()-ROW($O$3))*5,0,5,1)),2) -> 23.8
B12: l_4_35_5 | C12: 5368.02 | D12: 4.37 | E12: 0 | F12: 5368.02 | G12: 0 | H12: 354 | I12: 113 | J12: =H12+I12 -> 467 | L12: {=LEFT(INDEX($B:$B, ROW($B$3) + (ROW()-ROW($G$3))*5), LEN(INDEX($B:$B, ROW($B$3) + (ROW()-ROW($G$3))*5))-2)} -> n_4_35 | M12: =ROUND(AVERAGE(OFFSET($D$3,(ROW()-ROW($O$3))*5,0,5,1)),1) -> 0.3 | O12: {=LEFT(INDEX($B:$B, ROW($B$3) + (ROW()-ROW($G$3))*5), LEN(INDEX($B:$B, ROW($B$3) + (ROW()-ROW($G$3))*5))-2)} -> n_4_35 | P12: =AVERAGE(OFFSET($H$3,(ROW()-ROW($O$3))*5,0,5,1)) -> 55.6 | Q12: =ROUND(AVERAGE(OFFSET($I$3,(ROW()-ROW($O$3))*5,0,5,1)),2) -> 50.6 | S12: Size | T12: Median Routes Checked
B13: l_4_50_1 | C13: 7351.58 | D13: 4.57 | E13: 0 | F13: 7351.58 | G13: 0 | H13: 310 | I13: 248 | J13: =H13+I13 -> 558 | L13: {=LEFT(INDEX($B:$B, ROW($B$3) + (ROW()-ROW($G$3))*5), LEN(INDEX($B:$B, ROW($B$3) + (ROW()-ROW($G$3))*5))-2)} -> n_4_50 | M13: =ROUND(AVERAGE(OFFSET($D$3,(ROW()-ROW($O$3))*5,0,5,1)),1) -> 1 | O13: {=LEFT(INDEX($B:$B, ROW($B$3) + (ROW()-ROW($G$3))*5), LEN(INDEX($B:$B, ROW($B$3) + (ROW()-ROW($G$3))*5))-2)} -> n_4_50 | P13: =AVERAGE(OFFSET($H$3,(ROW()-ROW($O$3))*5,0,5,1)) -> 164.4 | Q13: =ROUND(AVERAGE(OFFSET($I$3,(ROW()-ROW($O$3))*5,0,5,1)),2) -> 136.2 | S13: n | T13: {=MEDIAN(_xlfn._xlws.FILTER($J$1:$J$122,ISNUMBER(SEARCH(INDIRECT("RC[-1]",0),$B$1:$B$122))))} -> 91.5
B14: l_4_50_2 | C14: 7253.39 | D14: 9.35 | E14: 0 | F14: 7253.39 | G14: 0 | H14: 835 | I14: 340 | J14: =H14+I14 -> 1175 | L14: {=LEFT(INDEX($B:$B, ROW($B$3) + (ROW()-ROW($G$3))*5), LEN(INDEX($B:$B, ROW($B$3) + (ROW()-ROW($G$3))*5))-2)} -> n_4_100 | M14: =ROUND(AVERAGE(OFFSET($D$3,(ROW()-ROW($O$3))*5,0,5,1)),1) -> 17.5 | O14: {=LEFT(INDEX($B:$B, ROW($B$3) + (ROW()-ROW($G$3))*5), LEN(INDEX($B:$B, ROW($B$3) + (ROW()-ROW($G$3))*5))-2)} -> n_4_100 | P14: =AVERAGE(OFFSET($H$3,(ROW()-ROW($O$3))*5,0,5,1)) -> 2062.6 | Q14: =ROUND(AVERAGE(OFFSET($I$3,(ROW()-ROW($O$3))*5,0,5,1)),2) -> 1208.4 | S14: l | T14: {=MEDIAN(_xlfn._xlws.FILTER($J$1:$J$122,ISNUMBER(SEARCH(INDIRECT("RC[-1]",0),$B$1:$B$122))))} -> 169
B15: l_4_50_3 | C15: 7485.02 | D15: 10.62 | E15: 0 | F15: 7485.02 | G15: 0 | H15: 483 | I15: 337 | J15: =H15+I15 -> 820 | L15: {=LEFT(INDEX($B:$B, ROW($B$3) + (ROW()-ROW($G$3))*5), LEN(INDEX($B:$B, ROW($B$3) + (ROW()-ROW($G$3))*5))-2)} -> n_8_25 | M15: =ROUND(AVERAGE(OFFSET($D$3,(ROW()-ROW($O$3))*5,0,5,1)),1) -> 0.1 | O15: {=LEFT(INDEX($B:$B, ROW($B$3) + (ROW()-ROW($G$3))*5), LEN(INDEX($B:$B, ROW($B$3) + (ROW()-ROW($G$3))*5))-2)} -> n_8_25 | P15: =AVERAGE(OFFSET($H$3,(ROW()-ROW($O$3))*5,0,5,1)) -> 13.4 | Q15: =ROUND(AVERAGE(OFFSET($I$3,(ROW()-ROW($O$3))*5,0,5,1)),2) -> 10.4 | S15: w | T15: {=MEDIAN(_xlfn._xlws.FILTER($J$1:$J$122,ISNUMBER(SEARCH(INDIRECT("RC[-1]",0),$B$1:$B$122))))} -> 959
B16: l_4_50_4 | C16: 6604.94 | D16: 8.2 | E16: 0 | F16: 6604.94 | G16: 0 | H16: 728 | I16: 490 | J16: =H16+I16 -> 1218 | L16: {=LEFT(INDEX($B:$B, ROW($B$3) + (ROW()-ROW($G$3))*5), LEN(INDEX($B:$B, ROW($B$3) + (ROW()-ROW($G$3))*5))-2)} -> n_8_35 | M16: =ROUND(AVERAGE(OFFSET($D$3,(ROW()-ROW($O$3))*5,0,5,1)),1) -> 0.2 | O16: {=LEFT(INDEX($B:$B, ROW($B$3) + (ROW()-ROW($G$3))*5), LEN(INDEX($B:$B, ROW($B$3) + (ROW()-ROW($G$3))*5))-2)} -> n_8_35 | P16: =AVERAGE(OFFSET($H$3,(ROW()-ROW($O$3))*5,0,5,1)) -> 15.4 | Q16: =ROUND(AVERAGE(OFFSET($I$3,(ROW()-ROW($O$3))*5,0,5,1)),2) -> 20.2
B17: l_4_50_5 | C17: 7370.88 | D17: 6.27 | E17: 0 | F17: 7370.88 | G17: 0 | H17: 470 | I17: 290 | J17: =H17+I17 -> 760 | L17: {=LEFT(INDEX($B:$B, ROW($B$3) + (ROW()-ROW($G$3))*5), LEN(INDEX($B:$B, ROW($B$3) + (ROW()-ROW($G$3))*5))-2)} -> n_8_50 | M17: =ROUND(AVERAGE(OFFSET($D$3,(ROW()-ROW($O$3))*5,0,5,1)),1) -> 0.4 | O17: {=LEFT(INDEX($B:$B, ROW($B$3) + (ROW()-ROW($G$3))*5), LEN(INDEX($B:$B, ROW($B$3) + (ROW()-ROW($G$3))*5))-2)} -> n_8_50 | P17: =AVERAGE(OFFSET($H$3,(ROW()-ROW($O$3))*5,0,5,1)) -> 31.4 | Q17: =ROUND(AVERAGE(OFFSET($I$3,(ROW()-ROW($O$3))*5,0,5,1)),2) -> 44.2
B18: l_4_100_1 | C18: 11458.17 | D18: 124.82 | E18: 1 | F18: 11462.64 | G18: 0.31 | H18: 7332 | I18: 5774 | J18: =H18+I18 -> 13106 | L18: {=LEFT(INDEX($B:$B, ROW($B$3) + (ROW()-ROW($G$3))*5), LEN(INDEX($B:$B, ROW($B$3) + (ROW()-ROW($G$3))*5))-2)} -> n_8_100 | M18: =ROUND(AVERAGE(OFFSET($D$3,(ROW()-ROW($O$3))*5,0,5,1)),1) -> 1.6 | O18: {=LEFT(INDEX($B:$B, ROW($B$3) + (ROW()-ROW($G$3))*5), LEN(INDEX($B:$B, ROW($B$3) + (ROW()-ROW($G$3))*5))-2)} -> n_8_100 | P18: =AVERAGE(OFFSET($H$3,(ROW()-ROW($O$3))*5,0,5,1)) -> 100.4 | Q18: =ROUND(AVERAGE(OFFSET($I$3,(ROW()-ROW($O$3))*5,0,5,1)),2) -> 203.8
B19: l_4_100_2 | C19: 12856.6 | D19: 521.37 | E19: 0 | F19: 12856.6 | G19: 0 | H19: 21801 | I19: 9895 | J19: =H19+I19 -> 31696 | L19: {=LEFT(INDEX($B:$B, ROW($B$3) + (ROW()-ROW($G$3))*5), LEN(INDEX($B:$B, ROW($B$3) + (ROW()-ROW($G$3))*5))-2)} -> w_4_25 | M19: =ROUND(AVERAGE(OFFSET($D$3,(ROW()-ROW($O$3))*5,0,5,1)),1) -> 2.6 | O19: {=LEFT(INDEX($B:$B, ROW($B$3) + (ROW()-ROW($G$3))*5), LEN(INDEX($B:$B, ROW($B$3) + (ROW()-ROW($G$3))*5))-2)} -> w_4_25 | P19: =AVERAGE(OFFSET($H$3,(ROW()-ROW($O$3))*5,0,5,1)) -> 256.8 | Q19: =ROUND(AVERAGE(OFFSET($I$3,(ROW()-ROW($O$3))*5,0,5,1)),2) -> 33
B20: l_4_100_3 | C20: 12966.97 | D20: 72.99 | E20: 0 | F20: 12966.97 | G20: 0 | H20: 3041 | I20: 2780 | J20: =H20+I20 -> 5821 | L20: {=LEFT(INDEX($B:$B, ROW($B$3) + (ROW()-ROW($G$3))*5), LEN(INDEX($B:$B, ROW($B$3) + (ROW()-ROW($G$3))*5))-2)} -> w_4_35 | M20: =ROUND(AVERAGE(OFFSET($D$3,(ROW()-ROW($O$3))*5,0,5,1)),1) -> 10.9 | O20: {=LEFT(INDEX($B:$B, ROW($B$3) + (ROW()-ROW($G$3))*5), LEN(INDEX($B:$B, ROW($B$3) + (ROW()-ROW($G$3))*5))-2)} -> w_4_35 | P20: =AVERAGE(OFFSET($H$3,(ROW()-ROW($O$3))*5,0,5,1)) -> 1611.8 | Q20: =ROUND(AVERAGE(OFFSET($I$3,(ROW()-ROW($O$3))*5,0,5,1)),2) -> 362.2
B21: l_4_100_4 | C21: 11111.41 | D21: 371.32 | E21: 1 | F21: 11139.38 | G21: 0.63 | H21: 18444 | I21: 7283 | J21: =H21+I21 -> 25727 | L21: {=LEFT(INDEX($B:$B, ROW($B$3) + (ROW()-ROW($G$3))*5), LEN(INDEX($B:$B, ROW($B$3) + (ROW()-ROW($G$3))*5))-2)} -> w_4_50 | M21: =ROUND(AVERAGE(OFFSET($D$3,(ROW()-ROW($O$3))*5,0,5,1)),1) -> 55.9 | O21: {=LEFT(INDEX($B:$B, ROW($B$3) + (ROW()-ROW($G$3))*5), LEN(INDEX($B:$B, ROW($B$3) + (ROW()-ROW($G$3))*5))-2)} -> w_4_50 | P21: =AVERAGE(OFFSET($H$3,(ROW()-ROW($O$3))*5,0,5,1)) -> 7853.2 | Q21: =ROUND(AVERAGE(OFFSET($I$3,(ROW()-ROW($O$3))*5,0,5,1)),2) -> 2496
B22: l_4_100_5 | C22: 11906.54 | D22: 230.04 | E22: 5 | F22: 12136.52 | G22: 1.43 | H22: 10126 | I22: 5853 | J22: =H22+I22 -> 15979 | L22: {=LEFT(INDEX($B:$B, ROW($B$3) + (ROW()-ROW($G$3))*5), LEN(INDEX($B:$B, ROW($B$3) + (ROW()-ROW($G$3))*5))-2)} -> w_4_100 | M22: =ROUND(D100,1) -> 1082.2 | O22: {=LEFT(INDEX($B:$B, ROW($B$3) + (ROW()-ROW($G$3))*5), LEN(INDEX($B:$B, ROW($B$3) + (ROW()-ROW($G$3))*5))-2)} -> w_4_100 | P22: =AVERAGE(OFFSET($H$3,(ROW()-ROW($O$3))*5,0,5,1)) -> 765990.4 | Q22: =ROUND(AVERAGE(OFFSET($I$3,(ROW()-ROW($O$3))*5,0,5,1)),2) -> 318328.4
B23: l_8_25_1 | C23: 3681.02 | D23: 0.36 | E23: 0 | F23: 3681.02 | G23: 0 | H23: 22 | I23: 7 | J23: =H23+I23 -> 29 | L23: {=LEFT(INDEX($B:$B, ROW($B$3) + (ROW()-ROW($G$3))*5), LEN(INDEX($B:$B, ROW($B$3) + (ROW()-ROW($G$3))*5))-2)} -> w_8_25 | M23: =ROUND(AVERAGE(OFFSET($D$3,(ROW()-ROW($O$3))*5,0,5,1)),1) -> 0.5 | O23: {=LEFT(INDEX($B:$B, ROW($B$3) + (ROW()-ROW($G$3))*5), LEN(INDEX($B:$B, ROW($B$3) + (ROW()-ROW($G$3))*5))-2)} -> w_8_25 | P23: =AVERAGE(OFFSET($H$3,(ROW()-ROW($O$3))*5,0,5,1)) -> 43 | Q23: =ROUND(AVERAGE(OFFSET($I$3,(ROW()-ROW($O$3))*5,0,5,1)),2) -> 6.4
B24: l_8_25_2 | C24: 4195.28 | D24: 0.26 | E24: 0 | F24: 4195.28 | G24: 0 | H24: 12 | I24: 5 | J24: =H24+I24 -> 17 | L24: {=LEFT(INDEX($B:$B, ROW($B$3) + (ROW()-ROW($G$3))*5), LEN(INDEX($B:$B, ROW($B$3) + (ROW()-ROW($G$3))*5))-2)} -> w_8_35 | M24: =ROUND(AVERAGE(OFFSET($D$3,(ROW()-ROW($O$3))*5,0,5,1)),1) -> 0.9 | O24: {=LEFT(INDEX($B:$B, ROW($B$3) + (ROW()-ROW($G$3))*5), LEN(INDEX($B:$B, ROW($B$3) + (ROW()-ROW($G$3))*5))-2)} -> w_8_35 | P24: =AVERAGE(OFFSET($H$3,(ROW()-ROW($O$3))*5,0,5,1)) -> 60.8 | Q24: =ROUND(AVERAGE(OFFSET($I$3,(ROW()-ROW($O$3))*5,0,5,1)),2) -> 21.6
B25: l_8_25_3 | C25: 3976.11 | D25: 1.19 | E25: 0 | F25: 3976.11 | G25: 0 | H25: 35 | I25: 13 | J25: =H25+I25 -> 48 | L25: {=LEFT(INDEX($B:$B, ROW($B$3) + (ROW()-ROW($G$3))*5), LEN(INDEX($B:$B, ROW($B$3) + (ROW()-ROW($G$3))*5))-2)} -> w_8_50 | M25: =ROUND(AVERAGE(OFFSET($D$3,(ROW()-ROW($O$3))*5,0,5,1)),1) -> 5 | O25: {=LEFT(INDEX($B:$B, ROW($B$3) + (ROW()-ROW($G$3))*5), LEN(INDEX($B:$B, ROW($B$3) + (ROW()-ROW($G$3))*5))-2)} -> w_8_50 | P25: =AVERAGE(OFFSET($H$3,(ROW()-ROW($O$3))*5,0,5,1)) -> 293.6 | Q25: =ROUND(AVERAGE(OFFSET($I$3,(ROW()-ROW($O$3))*5,0,5,1)),2) -> 107.6
B26: l_8_25_4 | C26: 4130.91 | D26: 0.17 | E26: 0 | F26: 4130.91 | G26: 0 | H26: 15 | I26: 9 | J26: =H26+I26 -> 24 | L26: {=LEFT(INDEX($B:$B, ROW($B$3) + (ROW()-ROW($G$3))*5), LEN(INDEX($B:$B, ROW($B$3) + (ROW()-ROW($G$3))*5))-2)} -> w_8_100 | M26: =ROUND(AVERAGE(OFFSET($D$3,(ROW()-ROW($O$3))*5,0,5,1)),1) -> 85.3 | O26: {=LEFT(INDEX($B:$B, ROW($B$3) + (ROW()-ROW($G$3))*5), LEN(INDEX($B:$B, ROW($B$3) + (ROW()-ROW($G$3))*5))-2)} -> w_8_100 | P26: =AVERAGE(OFFSET($H$3,(ROW()-ROW($O$3))*5,0,5,1)) -> 3953.4 | Q26: =ROUND(AVERAGE(OFFSET($I$3,(ROW()-ROW($O$3))*5,0,5,1)),2) -> 2499.2
B27: l_8_25_5 | C27: 6136.95 | D27: 0.21 | E27: 0 | F27: 6136.95 | G27: 0 | H27: 11 | I27: 10 | J27: =H27+I27 -> 21
B28: l_8_35_1 | C28: 5758.68 | D28: 0.52 | E28: 0 | F28: 5758.68 | G28: 0 | H28: 24 | I28: 21 | J28: =H28+I28 -> 45
B29: l_8_35_2 | C29: 5832.2 | D29: 0.32 | E29: 0 | F29: 5832.2 | G29: 0 | H29: 16 | I29: 16 | J29: =H29+I29 -> 32
B30: l_8_35_3 | C30: 5656.36 | D30: 1.04 | E30: 0 | F30: 5656.36 | G30: 0 | H30: 23 | I30: 13 | J30: =H30+I30 -> 36
B31: l_8_35_4 | C31: 5597.22 | D31: 0.81 | E31: 0 | F31: 5597.22 | G31: 0 | H31: 33 | I31: 16 | J31: =H31+I31 -> 49 | L31: Instance type | M31: # Corrected | N31: Avg Iters | O31: Avg Extra Time
B32: l_8_35_5 | C32: 6693.24 | D32: 0.36 | E32: 0 | F32: 6693.24 | G32: 0 | H32: 8 | I32: 13 | J32: =H32+I32 -> 21 | L32: l_4_100 | M32: 3 | N32: =ROUND(SUM(E18:E22)/M32,1) -> 2.3 | O32: =ROUND(SUM(G18:G22)/M32,1) -> 0.8
B33: l_8_50_1 | C33: 6221.15 | D33: 1.13 | E33: 0 | F33: 6221.15 | G33: 0 | H33: 45 | I33: 32 | J33: =H33+I33 -> 77 | L33: l_8_50 | M33: 2 | N33: =ROUND(SUM(E33:E37)/M33,2) -> 1 | O33: =ROUND(SUM(G33:G37)/M33,1) -> 0.1
B34: l_8_50_2 | C34: 8221.54 | D34: 1.25 | E34: 1 | F34: 8832.26 | G34: 0.01 | H34: 35 | I34: 36 | J34: =H34+I34 -> 71 | L34: l_8_100 | M34: 5 | N34: =ROUND(SUM(E38:E42)/$M$34,2) -> 1.6 | O34: =ROUND(SUM(G38:G42)/M34,1) -> 0.1
B35: l_8_50_3 | C35: 7071.04 | D35: 3.49 | E35: 0 | F35: 7071.04 | G35: 0 | H35: 100 | I35: 88 | J35: =H35+I35 -> 188 | L35: n_8_35 | M35: 1 | N35: =E69 -> 1 | O35: 0.1
B36: l_8_50_4 | C36: 6621.83 | D36: 1.28 | E36: 0 | F36: 6621.83 | G36: 0 | H36: 38 | I36: 38 | J36: =H36+I36 -> 76 | L36: n_8_50 | M36: 1 | N36: 1 | O36: 0.1
B37: l_8_50_5 | C37: 8650.61 | D37: 1.64 | E37: 1 | F37: 8712.62 | G37: 0.16 | H37: 80 | I37: 52 | J37: =H37+I37 -> 132 | L37: n_8_100 | M37: 1 | N37: 1 | O37: 0.1
B38: l_8_100_1 | C38: 12784.17 | D38: 11.14 | E38: 2 | F38: 13467.73 | G38: 0.17 | H38: 398 | I38: 352 | J38: =H38+I38 -> 750 | L38: w_4_35 | M38: 1 | N38: 2 | O38: 1
B39: l_8_100_2 | C39: 15043.14 | D39: 10.19 | E39: 1 | F39: 15248.09 | G39: 0.01 | H39: 162 | I39: 188 | J39: =H39+I39 -> 350 | L39: w_4_50 | M39: 1 | N39: 1 | O39: 0.5
B40: l_8_100_3 | C40: 14917.3 | D40: 9.91 | E40: 1 | F40: 14934.89 | G40: 0.06 | H40: 226 | I40: 361 | J40: =H40+I40 -> 587 | L40: w_8_25 | M40: 1 | N40: 1 | O40: 0.1
B41: l_8_100_4 | C41: 12720.69 | D41: 11.62 | E41: 2 | F41: 13715.23 | G41: 0.21 | H41: 325 | I41: 342 | J41: =H41+I41 -> 667 | L41: w_8_35 | M41: 5 | N41: =SUM(E108:E112)/M41 -> 1.4 | O41: =ROUND(SUM(G108:G112)/M41,1) -> 0.3
...

Sheet Sheet2
C7: Without | D7: Routes Checked | E7: With | F7: Routes Checked | G7: Diff
B8: l_4_100_1 | C8: =Sheet1!D18+Sheet1!G18 -> 125.13 | D8: =Sheet1!J18 -> 13106 | E8: 140.43 | F8: =7329+5775 -> 13104 | G8: =D8-F8 -> 2
B9: l_4_100_2 | C9: =Sheet1!D19+Sheet1!G19 -> 521.37 | D9: =Sheet1!J19 -> 31696 | E9: 723.32 | F9: =21792+9899 -> 31691 | G9: =D9-F9 -> 5
B10: l_4_100_3 | C10: =Sheet1!D20+Sheet1!G20 -> 72.99 | D10: =Sheet1!J20 -> 5821 | E10: 80.41 | F10: =3033+2771 -> 5804 | G10: =D10-F10 -> 17
B11: l_4_100_4 | C11: =Sheet1!D21+Sheet1!G21 -> 371.95 | D11: =Sheet1!J21 -> 25727 | E11: 453.75 | F11: =18419+7284 -> 25703 | G11: =D11-F11 -> 24
B12: l_4_100_5 | C12: =Sheet1!D22+Sheet1!G22 -> 231.47 | D12: =Sheet1!J22 -> 15979 | E12: 265.57 | F12: =10014+5847 -> 15861 | G12: =D12-F12 -> 118
B13: w_8_100_1 | C13: =Sheet1!D118+Sheet1!G118 -> 402.87 | D13: =Sheet1!J118 -> 8177 | E13: 868.86 | F13: =4211+2412 -> 6623 | G13: =D13-F13 -> 1554
B14: w_8_100_2 | C14: =Sheet1!D119+Sheet1!G119 -> 68.65 | D14: =Sheet1!J119 -> 2162 | E14: 149.4 | F14: =1104+767 -> 1871 | G14: =D14-F14 -> 291
B15: w_8_100_3 | C15: =Sheet1!D120+Sheet1!G120 -> 48.09 | D15: =Sheet1!J120 -> 3275 | E15: 96.56 | F15: =1713+1396 -> 3109 | G15: =D15-F15 -> 166
B16: w_8_100_4 | C16: =Sheet1!D121+Sheet1!G121 -> 262.7 | D16: =Sheet1!J121 -> 10975 | E16: 419.96 | F16: =5684+3162 -> 8846 | G16: =D16-F16 -> 2129
B17: w_8_100_5 | C17: =Sheet1!D122+Sheet1!G122 -> 98.48 | D17: =Sheet1!J122 -> 7674 | E17: 218.73 | F17: =4406+2734 -> 7140 | G17: =D17-F17 -> 534
B18: n_4_100_1 | C18: =Sheet1!D58+Sheet1!G58 -> 6.43 | D18: =Sheet1!J58 -> 2043 | E18: 8.55 | F18: =1052+991 -> 2043
B19: n_4_100_2 | C19: =Sheet1!D59+Sheet1!G59 -> 40.26 | D19: =Sheet1!J59 -> 6273 | E19: 46.09 | F19: =4452+1821 -> 6273
B20: n_4_100_3 | C20: =Sheet1!D60+Sheet1!G60 -> 7.36 | D20: =Sheet1!J60 -> 1212 | E20: 10.28 | F20: =527+685 -> 1212
B21: n_4_100_4 | C21: =Sheet1!D61+Sheet1!G61 -> 16.48 | D21: =Sheet1!J61 -> 3508 | E21: 19.79 | F21: =2323+1185 -> 3508
B22: n_4_100_5 | C22: =Sheet1!D62+Sheet1!G62 -> 17.14 | D22: =Sheet1!J62 -> 3319 | E22: 21.59 | F22: =1959+1360 -> 3319
C30: Total avg. time with post capacity correction (s) | D30: Avg Subproblems Ran | E30: Subproblem including Capacity Avg. Time (s) | F30: Avg Subproblems Ran
B31: n_4_100 | C31: =AVERAGE(C18:C22) -> 17.534 | D31: =ROUND(AVERAGE(D18:D22),1) -> 3271 | E31: =AVERAGE(E18:E22) -> 21.26 | F31: =ROUND(AVERAGE(F18:F22),1) -> 3271
B32: l_4_100 | C32: =ROUND(AVERAGE(C8:C12),2) -> 264.58 | D32: =ROUND(AVERAGE(D8:D12),1) -> 18465.8 | E32: =ROUND(AVERAGE(E8:E12),2) -> 332.7 | F32: =ROUND(AVERAGE(F8:F12),1) -> 18432.6
B33: w_8_100 | C33: =ROUND(AVERAGE(C13:C17),1) -> 176.2 | D33: =ROUND(AVERAGE(D13:D17),1) -> 6452.6 | E33: =ROUND(AVERAGE(E13:E17),1) -> 350.7 | F33: =ROUND(AVERAGE(F13:F17),1) -> 5517.8
